Traceback (most recent call last):
  File "/localscratch/alexort.47179598.0/env/lib/python3.11/site-packages/wandb/sdk/wandb_config.py", line 165, in __getattr__
    return self.__getitem__(key)
           ^^^^^^^^^^^^^^^^^^^^^
  File "/localscratch/alexort.47179598.0/env/lib/python3.11/site-packages/wandb/sdk/wandb_config.py", line 130, in __getitem__
    return self._items[key]
           ~~~~~~~~~~~^^^^^
KeyError: 'epochs'
The above exception was the direct cause of the following exception:
Traceback (most recent call last):
  File "<frozen runpy>", line 198, in _run_module_as_main
  File "<frozen runpy>", line 88, in _run_code
  File "/home/alexort/foundational_possum/scripts/run_training.py", line 87, in <module>
    main()
  File "/home/alexort/foundational_possum/scripts/run_training.py", line 73, in main
    train(
  File "/home/alexort/foundational_possum/src/models/training.py", line 33, in train
    {"epochs" :wandb.config.epochs + num_epochs},
               ^^^^^^^^^^^^^^^^^^^
  File "/localscratch/alexort.47179598.0/env/lib/python3.11/site-packages/wandb/sdk/wandb_config.py", line 167, in __getattr__
    raise AttributeError(
AttributeError: <class 'wandb.sdk.wandb_config.Config'> object has no attribute 'epochs'